<?xml version="1.0" ?>
<!-- =================================================================================== -->
<!-- |    This document was autogenerated by xacro from quadrupedal_robot.xacro        | -->
<!-- |    EDITING THIS FILE BY HAND IS NOT RECOMMENDED                                 | -->
<!-- =================================================================================== -->
<robot name="quadrupedal_robot" xmlns:xacro="https://ros.org/wiki/xacro">
  <link name="world"/>
  <joint name="world_joint" type="floating">
    <parent link="world"/>
    <child link="body"/>
    <origin rpy="0 0 0" xyz="0 0 0"/>
  </joint>
  <link name="body">
    <inertial>
      <mass value="1.43533"/>
      <inertia ixx="0.013997409758" ixy="0.0" ixz="0.0" iyy="0.032039793016" iyz="0.0" izz="0.029239204023"/>
    </inertial>
    <visual>
      <geometry>
        <mesh filename="package://quadrupedal_description/meshes/stl/body_assem_alt.stl"/>
      </geometry>
    </visual>
    <collision>
      <geometry>
        <mesh filename="package://quadrupedal_description/meshes/stl/body_assem_alt.stl"/>
      </geometry>
    </collision>
  </link>
  <gazebo reference="body">
    <material>Gazebo/Blue</material>
  </gazebo>
  <joint name="body_joint1" type="revolute">
    <parent link="body"/>
    <child link="upper_link1"/>
    <axis xyz="0 1 0"/>
    <origin rpy="0 0 0" xyz="0.15 -0.107 0.06"/>
    <dynamics damping="0.05"/>
    <limit effort="6.0" lower="-1.57" upper="1.57" velocity="6.0"/>
  </joint>
  <transmission name="body_joint_trans1">
    <type>transmission_interface/SimpleTransmission</type>
    <joint name="body_joint1">
      <hardwareInterface>hardware_interface/EffortJointInterface</hardwareInterface>
    </joint>
    <actuator name="body_motor1">
      <hardwareInterface>hardware_interface/EffortJointInterface</hardwareInterface>
      <mechanismReduction>1</mechanismReduction>
    </actuator>
  </transmission>
  <link name="upper_link1">
    <inertial>
      <mass value="0.307"/>
      <inertia ixx="0.0005696021" ixy="-9.8e-11" ixz="-2.43e-10" iyy="0.000513795097" iyz="7.4601225e-05" izz="0.000137674903"/>
    </inertial>
    <visual>
      <geometry>
        <mesh filename="package://quadrupedal_description/meshes/stl/upper_leg_alt.stl"/>
      </geometry>
    </visual>
    <collision>
      <geometry>
        <mesh filename="package://quadrupedal_description/meshes/stl/upper_leg_alt.stl"/>
      </geometry>
    </collision>
  </link>
  <gazebo reference="upper_link1">
    <material>Gazebo/Red</material>
  </gazebo>
  <joint name="upper_joint1" type="revolute">
    <parent link="upper_link1"/>
    <child link="under_link1"/>
    <axis xyz="0 1 0"/>
    <origin rpy="0 0 0" xyz="0 0.00425 -0.13"/>
    <dynamics damping="0.05"/>
    <limit effort="6.0" lower="-1.57" upper="1.57" velocity="6.0"/>
  </joint>
  <transmission name="upper_joint_trans1">
    <type>transmission_interface/SimpleTransmission</type>
    <joint name="upper_joint1">
      <hardwareInterface>hardware_interface/EffortJointInterface</hardwareInterface>
    </joint>
    <actuator name="upper_motor1">
      <hardwareInterface>hardware_interface/EffortJointInterface</hardwareInterface>
      <mechanismReduction>1</mechanismReduction>
    </actuator>
  </transmission>
  <link name="under_link1">
    <inertial>
      <mass value="0.080527"/>
      <inertia ixx="0.000400596397" ixy="1.83755e-07" ixz="-3.142145e-06" iyy="0.00040165997" iyz="2.0733392e-05" izz="6.738557e-06"/>
    </inertial>
    <visual>
      <geometry>
        <mesh filename="package://quadrupedal_description/meshes/stl/under_leg_alt.stl"/>
      </geometry>
    </visual>
    <collision>
      <geometry>
        <mesh filename="package://quadrupedal_description/meshes/stl/under_leg_alt.stl"/>
      </geometry>
    </collision>
  </link>
  <gazebo reference="under_link1">
    <material>Gazebo/Blue</material>
  </gazebo>
  <joint name="body_joint2" type="revolute">
    <parent link="body"/>
    <child link="upper_link2"/>
    <axis xyz="0 1 0"/>
    <origin rpy="0 0 0" xyz="-0.15 -0.107 0.06"/>
    <dynamics damping="0.05"/>
    <limit effort="6.0" lower="-1.57" upper="1.57" velocity="6.0"/>
  </joint>
  <transmission name="body_joint_trans2">
    <type>transmission_interface/SimpleTransmission</type>
    <joint name="body_joint2">
      <hardwareInterface>hardware_interface/EffortJointInterface</hardwareInterface>
    </joint>
    <actuator name="body_motor2">
      <hardwareInterface>hardware_interface/EffortJointInterface</hardwareInterface>
      <mechanismReduction>1</mechanismReduction>
    </actuator>
  </transmission>
  <link name="upper_link2">
    <inertial>
      <mass value="0.307"/>
      <inertia ixx="0.0005696021" ixy="-9.8e-11" ixz="-2.43e-10" iyy="0.000513795097" iyz="7.4601225e-05" izz="0.000137674903"/>
    </inertial>
    <visual>
      <geometry>
        <mesh filename="package://quadrupedal_description/meshes/stl/upper_leg_alt.stl"/>
      </geometry>
    </visual>
    <collision>
      <geometry>
        <mesh filename="package://quadrupedal_description/meshes/stl/upper_leg_alt.stl"/>
      </geometry>
    </collision>
  </link>
  <gazebo reference="upper_link2">
    <material>Gazebo/Red</material>
  </gazebo>
  <joint name="upper_joint2" type="revolute">
    <parent link="upper_link2"/>
    <child link="under_link2"/>
    <axis xyz="0 1 0"/>
    <origin rpy="0 0 0" xyz="0 0.00425 -0.13"/>
    <dynamics damping="0.05"/>
    <limit effort="6.0" lower="-1.57" upper="1.57" velocity="6.0"/>
  </joint>
  <transmission name="upper_joint_trans2">
    <type>transmission_interface/SimpleTransmission</type>
    <joint name="upper_joint2">
      <hardwareInterface>hardware_interface/EffortJointInterface</hardwareInterface>
    </joint>
    <actuator name="upper_motor2">
      <hardwareInterface>hardware_interface/EffortJointInterface</hardwareInterface>
      <mechanismReduction>1</mechanismReduction>
    </actuator>
  </transmission>
  <link name="under_link2">
    <inertial>
      <mass value="0.080527"/>
      <inertia ixx="0.000400596397" ixy="1.83755e-07" ixz="-3.142145e-06" iyy="0.00040165997" iyz="2.0733392e-05" izz="6.738557e-06"/>
    </inertial>
    <visual>
      <geometry>
        <mesh filename="package://quadrupedal_description/meshes/stl/under_leg_alt.stl"/>
      </geometry>
    </visual>
    <collision>
      <geometry>
        <mesh filename="package://quadrupedal_description/meshes/stl/under_leg_alt.stl"/>
      </geometry>
    </collision>
  </link>
  <gazebo reference="under_link2">
    <material>Gazebo/Blue</material>
  </gazebo>
  <joint name="body_joint3" type="revolute">
    <parent link="body"/>
    <child link="upper_link3"/>
    <axis xyz="0 1 0"/>
    <origin rpy="0 0 0" xyz="-0.15 0.107 0.06"/>
    <dynamics damping="0.05"/>
    <limit effort="6.0" lower="-1.57" upper="1.57" velocity="6.0"/>
  </joint>
  <transmission name="body_joint_trans3">
    <type>transmission_interface/SimpleTransmission</type>
    <joint name="body_joint3">
      <hardwareInterface>hardware_interface/EffortJointInterface</hardwareInterface>
    </joint>
    <actuator name="body_motor3">
      <hardwareInterface>hardware_interface/EffortJointInterface</hardwareInterface>
      <mechanismReduction>1</mechanismReduction>
    </actuator>
  </transmission>
  <link name="upper_link3">
    <inertial>
      <mass value="0.307"/>
      <inertia ixx="0.000569601994" ixy="1e-10" ixz="-2.43e-10" iyy="0.000513795026" iyz="-7.4601184e-05" izz="0.000137674854"/>
    </inertial>
    <visual>
      <geometry>
        <mesh filename="package://quadrupedal_description/meshes/stl/upper_leg_left_ease_alt.stl"/>
      </geometry>
    </visual>
    <collision>
      <geometry>
        <mesh filename="package://quadrupedal_description/meshes/stl/upper_leg_left_ease_alt.stl"/>
      </geometry>
    </collision>
  </link>
  <gazebo reference="upper_link3">
    <material>Gazebo/Red</material>
  </gazebo>
  <joint name="upper_joint3" type="revolute">
    <parent link="upper_link3"/>
    <child link="under_link3"/>
    <axis xyz="0 1 0"/>
    <origin rpy="0 0 0" xyz="0 -0.00425 -0.13"/>
    <dynamics damping="0.05"/>
    <limit effort="6.0" lower="-1.57" upper="1.57" velocity="6.0"/>
  </joint>
  <transmission name="upper_joint_trans3">
    <type>transmission_interface/SimpleTransmission</type>
    <joint name="upper_joint3">
      <hardwareInterface>hardware_interface/EffortJointInterface</hardwareInterface>
    </joint>
    <actuator name="upper_motor3">
      <hardwareInterface>hardware_interface/EffortJointInterface</hardwareInterface>
      <mechanismReduction>1</mechanismReduction>
    </actuator>
  </transmission>
  <link name="under_link3">
    <inertial>
      <mass value="0.080527"/>
      <inertia ixx="0.000400596397" ixy="-1.83755e-07" ixz="-3.142145e-06" iyy="0.00040165997" iyz="-2.0733392e-05" izz="6.738557e-06"/>
    </inertial>
    <visual>
      <geometry>
        <mesh filename="package://quadrupedal_description/meshes/stl/under_leg_left_ease_alt.stl"/>
      </geometry>
    </visual>
    <collision>
      <geometry>
        <mesh filename="package://quadrupedal_description/meshes/stl/under_leg_left_ease_alt.stl"/>
      </geometry>
    </collision>
  </link>
  <gazebo reference="under_link3">
    <material>Gazebo/Blue</material>
  </gazebo>
  <joint name="body_joint4" type="revolute">
    <parent link="body"/>
    <child link="upper_link4"/>
    <axis xyz="0 1 0"/>
    <origin rpy="0 0 0" xyz="0.15 0.107 0.06"/>
    <dynamics damping="0.05"/>
    <limit effort="6.0" lower="-1.57" upper="1.57" velocity="6.0"/>
  </joint>
  <transmission name="body_joint_trans4">
    <type>transmission_interface/SimpleTransmission</type>
    <joint name="body_joint4">
      <hardwareInterface>hardware_interface/EffortJointInterface</hardwareInterface>
    </joint>
    <actuator name="body_motor4">
      <hardwareInterface>hardware_interface/EffortJointInterface</hardwareInterface>
      <mechanismReduction>1</mechanismReduction>
    </actuator>
  </transmission>
  <link name="upper_link4">
    <inertial>
      <mass value="0.307"/>
      <inertia ixx="0.000569601994" ixy="1e-10" ixz="-2.43e-10" iyy="0.000513795026" iyz="-7.4601184e-05" izz="0.000137674854"/>
    </inertial>
    <visual>
      <geometry>
        <mesh filename="package://quadrupedal_description/meshes/stl/upper_leg_left_ease_alt.stl"/>
      </geometry>
    </visual>
    <collision>
      <geometry>
        <mesh filename="package://quadrupedal_description/meshes/stl/upper_leg_left_ease_alt.stl"/>
      </geometry>
    </collision>
  </link>
  <gazebo reference="upper_link4">
    <material>Gazebo/Red</material>
  </gazebo>
  <joint name="upper_joint4" type="revolute">
    <parent link="upper_link4"/>
    <child link="under_link4"/>
    <axis xyz="0 1 0"/>
    <origin rpy="0 0 0" xyz="0 -0.00425 -0.13"/>
    <dynamics damping="0.05"/>
    <limit effort="6.0" lower="-1.57" upper="1.57" velocity="6.0"/>
  </joint>
  <transmission name="upper_joint_trans4">
    <type>transmission_interface/SimpleTransmission</type>
    <joint name="upper_joint4">
      <hardwareInterface>hardware_interface/EffortJointInterface</hardwareInterface>
    </joint>
    <actuator name="upper_motor4">
      <hardwareInterface>hardware_interface/EffortJointInterface</hardwareInterface>
      <mechanismReduction>1</mechanismReduction>
    </actuator>
  </transmission>
  <link name="under_link4">
    <inertial>
      <mass value="0.080527"/>
      <inertia ixx="0.000400596397" ixy="-1.83755e-07" ixz="-3.142145e-06" iyy="0.00040165997" iyz="-2.0733392e-05" izz="6.738557e-06"/>
    </inertial>
    <visual>
      <geometry>
        <mesh filename="package://quadrupedal_description/meshes/stl/under_leg_left_ease_alt.stl"/>
      </geometry>
    </visual>
    <collision>
      <geometry>
        <mesh filename="package://quadrupedal_description/meshes/stl/under_leg_left_ease_alt.stl"/>
      </geometry>
    </collision>
  </link>
  <gazebo reference="under_link4">
    <material>Gazebo/Blue</material>
  </gazebo>
  <gazebo>
    <plugin filename="libgazebo_ros_control.so" name="gazebo_ros_control">
      <robotNamespace>/quadrupedal_robot</robotNamespace>
    </plugin>
  </gazebo>
</robot>

