<sdf version='1.6'>
  <world name='default'>
    <light name='sun' type='directional'>
      <cast_shadows>1</cast_shadows>
      <pose frame=''>0 0 10 0 -0 0</pose>
      <diffuse>0.8 0.8 0.8 1</diffuse>
      <specular>0.2 0.2 0.2 1</specular>
      <attenuation>
        <range>1000</range>
        <constant>0.9</constant>
        <linear>0.01</linear>
        <quadratic>0.001</quadratic>
      </attenuation>
      <direction>-0.5 0.1 -0.9</direction>
    </light>
    <model name='ground_plane'>
      <static>1</static>
      <link name='link'>
        <collision name='collision'>
          <geometry>
            <plane>
              <normal>0 0 1</normal>
              <size>100 100</size>
            </plane>
          </geometry>
          <surface>
            <friction>
              <ode>
                <mu>100</mu>
                <mu2>50</mu2>
              </ode>
              <torsional>
                <ode/>
              </torsional>
            </friction>
            <contact>
              <ode/>
            </contact>
            <bounce/>
          </surface>
          <max_contacts>10</max_contacts>
        </collision>
        <visual name='visual'>
          <cast_shadows>0</cast_shadows>
          <geometry>
            <plane>
              <normal>0 0 1</normal>
              <size>100 100</size>
            </plane>
          </geometry>
          <material>
            <script>
              <uri>file://media/materials/scripts/gazebo.material</uri>
              <name>Gazebo/Grey</name>
            </script>
          </material>
        </visual>
        <self_collide>0</self_collide>
        <kinematic>0</kinematic>
      </link>
    </model>
    <gravity>0 0 -9.8</gravity>
    <magnetic_field>6e-06 2.3e-05 -4.2e-05</magnetic_field>
    <atmosphere type='adiabatic'/>
    <physics name='default_physics' default='0' type='ode'>
      <max_step_size>0.001</max_step_size>
      <real_time_factor>1</real_time_factor>
      <real_time_update_rate>1000</real_time_update_rate>
    </physics>
    <scene>
      <ambient>0.4 0.4 0.4 1</ambient>
      <background>0.7 0.7 0.7 1</background>
      <shadows>1</shadows>
    </scene>
    <spherical_coordinates>
      <surface_model>EARTH_WGS84</surface_model>
      <latitude_deg>0</latitude_deg>
      <longitude_deg>0</longitude_deg>
      <elevation>0</elevation>
      <heading_deg>0</heading_deg>
    </spherical_coordinates>
    <model name='cinder_block'>
      <link name='link'>
        <inertial>
          <pose frame=''>0 0 0.1016 0 -0 0</pose>
          <mass>5</mass>
          <inertia>
            <ixx>0.028705</ixx>
            <ixy>0</ixy>
            <iyy>0.073708</iyy>
            <ixz>0</ixz>
            <iyz>0</iyz>
            <izz>0.06908</izz>
          </inertia>
        </inertial>
        <visual name='visual'>
          <geometry>
            <mesh>
              <uri>model://cinder_block/meshes/cinder_block.dae</uri>
            </mesh>
          </geometry>
        </visual>
        <collision name='left'>
          <pose frame=''>0 -0.08465 0.1016 0 -0 0</pose>
          <geometry>
            <box>
              <size>0.43495 0.0339 0.2032</size>
            </box>
          </geometry>
          <surface>
            <contact>
              <ode>
                <max_vel>0.1</max_vel>
                <min_depth>0.001</min_depth>
              </ode>
            </contact>
            <friction>
              <ode>
                <mu>1</mu>
                <mu2>1</mu2>
              </ode>
              <torsional>
                <ode/>
              </torsional>
            </friction>
            <bounce/>
          </surface>
          <max_contacts>10</max_contacts>
        </collision>
        <collision name='right'>
          <pose frame=''>0 0.08465 0.1016 0 -0 0</pose>
          <geometry>
            <box>
              <size>0.43495 0.0339 0.2032</size>
            </box>
          </geometry>
          <surface>
            <contact>
              <ode>
                <max_vel>0.1</max_vel>
                <min_depth>0.001</min_depth>
              </ode>
            </contact>
            <friction>
              <ode>
                <mu>1</mu>
                <mu2>1</mu2>
              </ode>
              <torsional>
                <ode/>
              </torsional>
            </friction>
            <bounce/>
          </surface>
          <max_contacts>10</max_contacts>
        </collision>
        <collision name='front'>
          <pose frame=''>0.18625 0 0.1016 0 -0 0</pose>
          <geometry>
            <box>
              <size>0.0339 0.1354 0.203</size>
            </box>
          </geometry>
          <surface>
            <contact>
              <ode>
                <max_vel>0.1</max_vel>
                <min_depth>0.001</min_depth>
              </ode>
            </contact>
            <friction>
              <ode>
                <mu>1</mu>
                <mu2>1</mu2>
              </ode>
              <torsional>
                <ode/>
              </torsional>
            </friction>
            <bounce/>
          </surface>
          <max_contacts>10</max_contacts>
        </collision>
        <collision name='middle'>
          <pose frame=''>0 0 0.1016 0 -0 0</pose>
          <geometry>
            <box>
              <size>0.0339 0.1354 0.203</size>
            </box>
          </geometry>
          <surface>
            <contact>
              <ode>
                <max_vel>0.1</max_vel>
                <min_depth>0.001</min_depth>
              </ode>
            </contact>
            <friction>
              <ode>
                <mu>1</mu>
                <mu2>1</mu2>
              </ode>
              <torsional>
                <ode/>
              </torsional>
            </friction>
            <bounce/>
          </surface>
          <max_contacts>10</max_contacts>
        </collision>
        <collision name='back'>
          <pose frame=''>-0.18625 0 0.1016 0 -0 0</pose>
          <geometry>
            <box>
              <size>0.0339 0.1354 0.203</size>
            </box>
          </geometry>
          <surface>
            <contact>
              <ode>
                <max_vel>0.1</max_vel>
                <min_depth>0.001</min_depth>
              </ode>
            </contact>
            <friction>
              <ode>
                <mu>1</mu>
                <mu2>1</mu2>
              </ode>
              <torsional>
                <ode/>
              </torsional>
            </friction>
            <bounce/>
          </surface>
          <max_contacts>10</max_contacts>
        </collision>
        <self_collide>0</self_collide>
        <kinematic>0</kinematic>
      </link>
      <pose frame=''>0.85761 -0.105907 0 0 -0 0</pose>
    </model>
    <model name='Dumpster'>
      <link name='link'>
        <collision name='collision'>
          <geometry>
            <mesh>
              <scale>1.5 1.5 1.5</scale>
              <uri>model://dumpster/meshes/dumpster.dae</uri>
            </mesh>
          </geometry>
          <max_contacts>10</max_contacts>
          <surface>
            <contact>
              <ode/>
            </contact>
            <bounce/>
            <friction>
              <torsional>
                <ode/>
              </torsional>
              <ode/>
            </friction>
          </surface>
        </collision>
        <visual name='visual'>
          <geometry>
            <mesh>
              <scale>1.5 1.5 1.5</scale>
              <uri>model://dumpster/meshes/dumpster.dae</uri>
            </mesh>
          </geometry>
          <material>
            <script>
              <uri>model://dumpster/materials/scripts</uri>
              <uri>model://dumpster/materials/textures</uri>
              <name>Dumpster/Diffuse</name>
            </script>
          </material>
        </visual>
        <self_collide>0</self_collide>
        <inertial>
          <inertia>
            <ixx>1</ixx>
            <ixy>0</ixy>
            <ixz>0</ixz>
            <iyy>1</iyy>
            <iyz>0</iyz>
            <izz>1</izz>
          </inertia>
          <mass>1</mass>
        </inertial>
        <kinematic>0</kinematic>
      </link>
      <pose frame=''>-2.07108 -0.460202 0 0 -0 0</pose>
    </model>
    <model name='fire_hydrant'>
      <static>1</static>
      <link name='link'>
        <collision name='collision'>
          <geometry>
            <mesh>
              <uri>model://fire_hydrant/meshes/fire_hydrant.dae</uri>
            </mesh>
          </geometry>
          <max_contacts>10</max_contacts>
          <surface>
            <contact>
              <ode/>
            </contact>
            <bounce/>
            <friction>
              <torsional>
                <ode/>
              </torsional>
              <ode/>
            </friction>
          </surface>
        </collision>
        <visual name='visual'>
          <geometry>
            <mesh>
              <uri>model://fire_hydrant/meshes/fire_hydrant.dae</uri>
            </mesh>
          </geometry>
        </visual>
        <self_collide>0</self_collide>
        <kinematic>0</kinematic>
      </link>
      <pose frame=''>-0.813705 -2.73929 0 0 -0 0</pose>
    </model>
    <model name='ground_plane_0'>
      <static>1</static>
      <link name='link'>
        <collision name='collision'>
          <geometry>
            <plane>
              <normal>0 0 1</normal>
              <size>100 100</size>
            </plane>
          </geometry>
          <surface>
            <friction>
              <ode>
                <mu>100</mu>
                <mu2>50</mu2>
              </ode>
              <torsional>
                <ode/>
              </torsional>
            </friction>
            <contact>
              <ode/>
            </contact>
            <bounce/>
          </surface>
          <max_contacts>10</max_contacts>
        </collision>
        <visual name='visual'>
          <cast_shadows>0</cast_shadows>
          <geometry>
            <plane>
              <normal>0 0 1</normal>
              <size>100 100</size>
            </plane>
          </geometry>
          <material>
            <script>
              <uri>file://media/materials/scripts/gazebo.material</uri>
              <name>Gazebo/Grey</name>
            </script>
          </material>
        </visual>
        <self_collide>0</self_collide>
        <kinematic>0</kinematic>
      </link>
      <pose frame=''>0.276228 -2.32772 0 0 -0 0</pose>
    </model>
    <model name='ground_plane_1'>
      <static>1</static>
      <link name='link'>
        <collision name='collision'>
          <geometry>
            <plane>
              <normal>0 0 1</normal>
              <size>100 100</size>
            </plane>
          </geometry>
          <surface>
            <friction>
              <ode>
                <mu>100</mu>
                <mu2>50</mu2>
              </ode>
              <torsional>
                <ode/>
              </torsional>
            </friction>
            <contact>
              <ode/>
            </contact>
            <bounce/>
          </surface>
          <max_contacts>10</max_contacts>
        </collision>
        <visual name='visual'>
          <cast_shadows>0</cast_shadows>
          <geometry>
            <plane>
              <normal>0 0 1</normal>
              <size>100 100</size>
            </plane>
          </geometry>
          <material>
            <script>
              <uri>file://media/materials/scripts/gazebo.material</uri>
              <name>Gazebo/Grey</name>
            </script>
          </material>
        </visual>
        <self_collide>0</self_collide>
        <kinematic>0</kinematic>
      </link>
      <pose frame=''>-77.2838 49.0164 0 0 -0 0</pose>
    </model>
    <model name='legged_robot'>
      <static>0</static>
      <link name='torso'>
        <pose frame=''>0 0 0.6 0 -0 0</pose>
        <inertial>
          <mass>10</mass>
          <inertia>
            <ixx>0.07</ixx>
            <iyy>0.08</iyy>
            <izz>0.1</izz>
            <ixy>0</ixy>
            <ixz>0</ixz>
            <iyz>0</iyz>
          </inertia>
        </inertial>
        <collision name='collision'>
          <geometry>
            <box>
              <size>0.5 0.3 0.05</size>
            </box>
          </geometry>
          <max_contacts>10</max_contacts>
          <surface>
            <contact>
              <ode/>
            </contact>
            <bounce/>
            <friction>
              <torsional>
                <ode/>
              </torsional>
              <ode/>
            </friction>
          </surface>
        </collision>
        <visual name='visual'>
          <geometry>
            <box>
              <size>0.5 0.3 0.05</size>
            </box>
          </geometry>
        </visual>
        <self_collide>0</self_collide>
        <kinematic>0</kinematic>
      </link>
      <link name='base_left_fore'>
        <pose frame=''>0.23 0.17 0.595 1.5707 -0 0</pose>
        <visual name='visual'>
          <geometry>
            <cylinder>
              <radius>0.025</radius>
              <length>0.05</length>
            </cylinder>
          </geometry>
        </visual>
        <self_collide>0</self_collide>
        <inertial>
          <inertia>
            <ixx>1</ixx>
            <ixy>0</ixy>
            <ixz>0</ixz>
            <iyy>1</iyy>
            <iyz>0</iyz>
            <izz>1</izz>
          </inertia>
          <mass>1</mass>
        </inertial>
        <kinematic>0</kinematic>
      </link>
      <link name='base_left_rear'>
        <pose frame=''>-0.23 0.17 0.595 1.5707 -0 0</pose>
        <visual name='visual'>
          <geometry>
            <cylinder>
              <radius>0.025</radius>
              <length>0.05</length>
            </cylinder>
          </geometry>
        </visual>
        <self_collide>0</self_collide>
        <inertial>
          <inertia>
            <ixx>1</ixx>
            <ixy>0</ixy>
            <ixz>0</ixz>
            <iyy>1</iyy>
            <iyz>0</iyz>
            <izz>1</izz>
          </inertia>
          <mass>1</mass>
        </inertial>
        <kinematic>0</kinematic>
      </link>
      <link name='base_right_fore'>
        <pose frame=''>0.23 -0.17 0.595 1.5707 -0 0</pose>
        <visual name='visual'>
          <geometry>
            <cylinder>
              <radius>0.025</radius>
              <length>0.05</length>
            </cylinder>
          </geometry>
        </visual>
        <self_collide>0</self_collide>
        <inertial>
          <inertia>
            <ixx>1</ixx>
            <ixy>0</ixy>
            <ixz>0</ixz>
            <iyy>1</iyy>
            <iyz>0</iyz>
            <izz>1</izz>
          </inertia>
          <mass>1</mass>
        </inertial>
        <kinematic>0</kinematic>
      </link>
      <link name='base_right_rear'>
        <pose frame=''>-0.23 -0.17 0.595 1.5707 -0 0</pose>
        <visual name='visual'>
          <geometry>
            <cylinder>
              <radius>0.025</radius>
              <length>0.05</length>
            </cylinder>
          </geometry>
        </visual>
        <self_collide>0</self_collide>
        <inertial>
          <inertia>
            <ixx>1</ixx>
            <ixy>0</ixy>
            <ixz>0</ixz>
            <iyy>1</iyy>
            <iyz>0</iyz>
            <izz>1</izz>
          </inertia>
          <mass>1</mass>
        </inertial>
        <kinematic>0</kinematic>
      </link>
      <link name='link_left_fore_lower'>
        <self_collide>0</self_collide>
        <pose frame=''>0.23 0.17 0.15 0 -0 0</pose>
        <inertial>
          <inertia>
            <ixx>0.01</ixx>
            <ixy>0</ixy>
            <ixz>0</ixz>
            <iyy>0.01</iyy>
            <iyz>0</iyz>
            <izz>0.01</izz>
          </inertia>
          <mass>2</mass>
        </inertial>
        <collision name='collision'>
          <geometry>
            <cylinder>
              <radius>0.02</radius>
              <length>0.3</length>
            </cylinder>
          </geometry>
          <surface>
            <friction>
              <ode>
                <mu>100000</mu>
                <mu2>100000</mu2>
                <slip1>0</slip1>
                <slip2>0</slip2>
              </ode>
              <torsional>
                <ode/>
              </torsional>
            </friction>
            <contact>
              <ode/>
            </contact>
            <bounce/>
          </surface>
          <max_contacts>10</max_contacts>
        </collision>
        <visual name='visual'>
          <geometry>
            <cylinder>
              <radius>0.02</radius>
              <length>0.3</length>
            </cylinder>
          </geometry>
        </visual>
        <kinematic>0</kinematic>
      </link>
      <link name='link_left_rear_lower'>
        <self_collide>0</self_collide>
        <pose frame=''>-0.23 0.17 0.15 0 -0 0</pose>
        <inertial>
          <inertia>
            <ixx>0.01</ixx>
            <ixy>0</ixy>
            <ixz>0</ixz>
            <iyy>0.01</iyy>
            <iyz>0</iyz>
            <izz>0.01</izz>
          </inertia>
          <mass>2</mass>
        </inertial>
        <collision name='collision'>
          <geometry>
            <cylinder>
              <radius>0.02</radius>
              <length>0.3</length>
            </cylinder>
          </geometry>
          <surface>
            <friction>
              <ode>
                <mu>100000</mu>
                <mu2>100000</mu2>
                <slip1>0</slip1>
                <slip2>0</slip2>
              </ode>
              <torsional>
                <ode/>
              </torsional>
            </friction>
            <contact>
              <ode/>
            </contact>
            <bounce/>
          </surface>
          <max_contacts>10</max_contacts>
        </collision>
        <visual name='visual'>
          <geometry>
            <cylinder>
              <radius>0.02</radius>
              <length>0.3</length>
            </cylinder>
          </geometry>
        </visual>
        <kinematic>0</kinematic>
      </link>
      <link name='link_right_fore_lower'>
        <self_collide>0</self_collide>
        <pose frame=''>0.23 -0.17 0.15 0 -0 0</pose>
        <inertial>
          <inertia>
            <ixx>0.01</ixx>
            <ixy>0</ixy>
            <ixz>0</ixz>
            <iyy>0.01</iyy>
            <iyz>0</iyz>
            <izz>0.01</izz>
          </inertia>
          <mass>2</mass>
        </inertial>
        <collision name='collision'>
          <geometry>
            <cylinder>
              <radius>0.02</radius>
              <length>0.3</length>
            </cylinder>
          </geometry>
          <surface>
            <friction>
              <ode>
                <mu>100000</mu>
                <mu2>100000</mu2>
                <slip1>0</slip1>
                <slip2>0</slip2>
              </ode>
              <torsional>
                <ode/>
              </torsional>
            </friction>
            <contact>
              <ode/>
            </contact>
            <bounce/>
          </surface>
          <max_contacts>10</max_contacts>
        </collision>
        <visual name='visual'>
          <geometry>
            <cylinder>
              <radius>0.02</radius>
              <length>0.3</length>
            </cylinder>
          </geometry>
        </visual>
        <kinematic>0</kinematic>
      </link>
      <link name='link_right_rear_lower'>
        <self_collide>0</self_collide>
        <pose frame=''>-0.23 -0.17 0.15 0 -0 0</pose>
        <inertial>
          <inertia>
            <ixx>0.01</ixx>
            <ixy>0</ixy>
            <ixz>0</ixz>
            <iyy>0.01</iyy>
            <iyz>0</iyz>
            <izz>0.01</izz>
          </inertia>
          <mass>2</mass>
        </inertial>
        <collision name='collision'>
          <geometry>
            <cylinder>
              <radius>0.02</radius>
              <length>0.3</length>
            </cylinder>
          </geometry>
          <surface>
            <friction>
              <ode>
                <mu>100000</mu>
                <mu2>100000</mu2>
                <slip1>0</slip1>
                <slip2>0</slip2>
              </ode>
              <torsional>
                <ode/>
              </torsional>
            </friction>
            <contact>
              <ode/>
            </contact>
            <bounce/>
          </surface>
          <max_contacts>10</max_contacts>
        </collision>
        <visual name='visual'>
          <geometry>
            <cylinder>
              <radius>0.02</radius>
              <length>0.3</length>
            </cylinder>
          </geometry>
        </visual>
        <kinematic>0</kinematic>
      </link>
      <link name='link_left_fore_upper'>
        <self_collide>0</self_collide>
        <pose frame=''>0.23 0.17 0.45 0 -0 0</pose>
        <inertial>
          <inertia>
            <ixx>0.01</ixx>
            <ixy>0</ixy>
            <ixz>0</ixz>
            <iyy>0.01</iyy>
            <iyz>0</iyz>
            <izz>0.01</izz>
          </inertia>
          <mass>2</mass>
        </inertial>
        <visual name='visual'>
          <geometry>
            <cylinder>
              <radius>0.02</radius>
              <length>0.3</length>
            </cylinder>
          </geometry>
        </visual>
        <kinematic>0</kinematic>
      </link>
      <link name='link_left_rear_upper'>
        <self_collide>0</self_collide>
        <pose frame=''>-0.23 0.17 0.45 0 -0 0</pose>
        <inertial>
          <inertia>
            <ixx>0.01</ixx>
            <ixy>0</ixy>
            <ixz>0</ixz>
            <iyy>0.01</iyy>
            <iyz>0</iyz>
            <izz>0.01</izz>
          </inertia>
          <mass>2</mass>
        </inertial>
        <visual name='visual'>
          <geometry>
            <cylinder>
              <radius>0.02</radius>
              <length>0.3</length>
            </cylinder>
          </geometry>
        </visual>
        <kinematic>0</kinematic>
      </link>
      <link name='link_right_fore_upper'>
        <self_collide>0</self_collide>
        <pose frame=''>0.23 -0.17 0.45 0 -0 0</pose>
        <inertial>
          <inertia>
            <ixx>0.01</ixx>
            <ixy>0</ixy>
            <ixz>0</ixz>
            <iyy>0.01</iyy>
            <iyz>0</iyz>
            <izz>0.01</izz>
          </inertia>
          <mass>2</mass>
        </inertial>
        <visual name='visual'>
          <geometry>
            <cylinder>
              <radius>0.02</radius>
              <length>0.3</length>
            </cylinder>
          </geometry>
        </visual>
        <kinematic>0</kinematic>
      </link>
      <link name='link_right_rear_upper'>
        <self_collide>0</self_collide>
        <pose frame=''>-0.23 -0.17 0.45 0 -0 0</pose>
        <inertial>
          <inertia>
            <ixx>0.01</ixx>
            <ixy>0</ixy>
            <ixz>0</ixz>
            <iyy>0.01</iyy>
            <iyz>0</iyz>
            <izz>0.01</izz>
          </inertia>
          <mass>2</mass>
        </inertial>
        <visual name='visual'>
          <geometry>
            <cylinder>
              <radius>0.02</radius>
              <length>0.3</length>
            </cylinder>
          </geometry>
        </visual>
        <kinematic>0</kinematic>
      </link>
      <joint name='hinge_lf1' type='revolute'>
        <pose frame=''>0 0 0 0 -0 0</pose>
        <child>base_left_fore</child>
        <parent>torso</parent>
        <axis>
          <xyz>0 1 0</xyz>
          <use_parent_model_frame>1</use_parent_model_frame>
          <limit>
            <lower>-1e+16</lower>
            <upper>1e+16</upper>
          </limit>
          <dynamics>
            <spring_reference>0</spring_reference>
            <spring_stiffness>0</spring_stiffness>
          </dynamics>
        </axis>
      </joint>
      <joint name='hinge_lr1' type='revolute'>
        <pose frame=''>0 0 0 0 -0 0</pose>
        <child>base_left_rear</child>
        <parent>torso</parent>
        <axis>
          <xyz>0 1 0</xyz>
          <use_parent_model_frame>1</use_parent_model_frame>
          <limit>
            <lower>-1e+16</lower>
            <upper>1e+16</upper>
          </limit>
          <dynamics>
            <spring_reference>0</spring_reference>
            <spring_stiffness>0</spring_stiffness>
          </dynamics>
        </axis>
      </joint>
      <joint name='hinge_rf1' type='revolute'>
        <pose frame=''>0 0 0 0 -0 0</pose>
        <child>base_right_fore</child>
        <parent>torso</parent>
        <axis>
          <xyz>0 1 0</xyz>
          <use_parent_model_frame>1</use_parent_model_frame>
          <limit>
            <lower>-1e+16</lower>
            <upper>1e+16</upper>
          </limit>
          <dynamics>
            <spring_reference>0</spring_reference>
            <spring_stiffness>0</spring_stiffness>
          </dynamics>
        </axis>
      </joint>
      <joint name='hinge_rr1' type='revolute'>
        <pose frame=''>0 0 0 0 -0 0</pose>
        <child>base_right_rear</child>
        <parent>torso</parent>
        <axis>
          <xyz>0 1 0</xyz>
          <use_parent_model_frame>1</use_parent_model_frame>
          <limit>
            <lower>-1e+16</lower>
            <upper>1e+16</upper>
          </limit>
          <dynamics>
            <spring_reference>0</spring_reference>
            <spring_stiffness>0</spring_stiffness>
          </dynamics>
        </axis>
      </joint>
      <joint name='hinge_lf2' type='revolute'>
        <pose frame=''>0 0 0.15 0 -0 0</pose>
        <child>link_left_fore_upper</child>
        <parent>base_left_fore</parent>
        <axis>
          <xyz>1 0 0</xyz>
          <use_parent_model_frame>1</use_parent_model_frame>
          <limit>
            <lower>-1e+16</lower>
            <upper>1e+16</upper>
          </limit>
          <dynamics>
            <spring_reference>0</spring_reference>
            <spring_stiffness>0</spring_stiffness>
          </dynamics>
        </axis>
      </joint>
      <joint name='hinge_lr2' type='revolute'>
        <pose frame=''>0 0 0.15 0 -0 0</pose>
        <child>link_left_rear_upper</child>
        <parent>base_left_rear</parent>
        <axis>
          <xyz>1 0 0</xyz>
          <use_parent_model_frame>1</use_parent_model_frame>
          <limit>
            <lower>-1e+16</lower>
            <upper>1e+16</upper>
          </limit>
          <dynamics>
            <spring_reference>0</spring_reference>
            <spring_stiffness>0</spring_stiffness>
          </dynamics>
        </axis>
      </joint>
      <joint name='hinge_rf2' type='revolute'>
        <pose frame=''>0 0 0.15 0 -0 0</pose>
        <child>link_right_fore_upper</child>
        <parent>base_right_fore</parent>
        <axis>
          <xyz>1 0 0</xyz>
          <use_parent_model_frame>1</use_parent_model_frame>
          <limit>
            <lower>-1e+16</lower>
            <upper>1e+16</upper>
          </limit>
          <dynamics>
            <spring_reference>0</spring_reference>
            <spring_stiffness>0</spring_stiffness>
          </dynamics>
        </axis>
      </joint>
      <joint name='hinge_rr2' type='revolute'>
        <pose frame=''>0 0 0.15 0 -0 0</pose>
        <child>link_right_rear_upper</child>
        <parent>base_right_rear</parent>
        <axis>
          <xyz>1 0 0</xyz>
          <use_parent_model_frame>1</use_parent_model_frame>
          <limit>
            <lower>-1e+16</lower>
            <upper>1e+16</upper>
          </limit>
          <dynamics>
            <spring_reference>0</spring_reference>
            <spring_stiffness>0</spring_stiffness>
          </dynamics>
        </axis>
      </joint>
      <joint name='hinge_lf3' type='revolute'>
        <pose frame=''>0 0 0.15 0 -0 0</pose>
        <child>link_left_fore_lower</child>
        <parent>link_left_fore_upper</parent>
        <axis>
          <xyz>0 1 0</xyz>
          <use_parent_model_frame>1</use_parent_model_frame>
          <limit>
            <lower>-1e+16</lower>
            <upper>1e+16</upper>
          </limit>
          <dynamics>
            <spring_reference>0</spring_reference>
            <spring_stiffness>0</spring_stiffness>
          </dynamics>
        </axis>
      </joint>
      <joint name='hinge_lr3' type='revolute'>
        <pose frame=''>0 0 0.15 0 -0 0</pose>
        <child>link_left_rear_lower</child>
        <parent>link_left_rear_upper</parent>
        <axis>
          <xyz>0 1 0</xyz>
          <use_parent_model_frame>1</use_parent_model_frame>
          <limit>
            <lower>-1e+16</lower>
            <upper>1e+16</upper>
          </limit>
          <dynamics>
            <spring_reference>0</spring_reference>
            <spring_stiffness>0</spring_stiffness>
          </dynamics>
        </axis>
      </joint>
      <joint name='hinge_rf3' type='revolute'>
        <pose frame=''>0 0 0.15 0 -0 0</pose>
        <child>link_right_fore_lower</child>
        <parent>link_right_fore_upper</parent>
        <axis>
          <xyz>0 1 0</xyz>
          <use_parent_model_frame>1</use_parent_model_frame>
          <limit>
            <lower>-1e+16</lower>
            <upper>1e+16</upper>
          </limit>
          <dynamics>
            <spring_reference>0</spring_reference>
            <spring_stiffness>0</spring_stiffness>
          </dynamics>
        </axis>
      </joint>
      <joint name='hinge_rr3' type='revolute'>
        <pose frame=''>0 0 0.15 0 -0 0</pose>
        <child>link_right_rear_lower</child>
        <parent>link_right_rear_upper</parent>
        <axis>
          <xyz>0 1 0</xyz>
          <use_parent_model_frame>1</use_parent_model_frame>
          <limit>
            <lower>-1e+16</lower>
            <upper>1e+16</upper>
          </limit>
          <dynamics>
            <spring_reference>0</spring_reference>
            <spring_stiffness>0</spring_stiffness>
          </dynamics>
        </axis>
      </joint>
      <plugin name='legged' filename='liblegged.so'>
        <hinge_lf1>hinge_lf1</hinge_lf1>
        <hinge_lf2>hinge_lf2</hinge_lf2>
        <hinge_lf3>hinge_lf3</hinge_lf3>
        <hinge_lr1>hinge_lr1</hinge_lr1>
        <hinge_lr2>hinge_lr2</hinge_lr2>
        <hinge_lr3>hinge_lr3</hinge_lr3>
        <hinge_rf1>hinge_rf1</hinge_rf1>
        <hinge_rf2>hinge_rf2</hinge_rf2>
        <hinge_rf3>hinge_rf3</hinge_rf3>
        <hinge_rr1>hinge_rr1</hinge_rr1>
        <hinge_rr2>hinge_rr2</hinge_rr2>
        <hinge_rr3>hinge_rr3</hinge_rr3>
        <gain>0.1</gain>
        <sensor>sensor</sensor>
        <ray_sensor>laser</ray_sensor>
      </plugin>
      <pose frame=''>-2.26817 -1.96407 0 0 -0 0</pose>
    </model>
    <model name='pioneer2dx'>
      <link name='chassis'>
        <pose frame=''>0 0 0.16 0 -0 0</pose>
        <inertial>
          <mass>5.67</mass>
          <inertia>
            <ixx>0.07</ixx>
            <iyy>0.08</iyy>
            <izz>0.1</izz>
            <ixy>0</ixy>
            <ixz>0</ixz>
            <iyz>0</iyz>
          </inertia>
        </inertial>
        <collision name='collision'>
          <geometry>
            <box>
              <size>0.445 0.277 0.17</size>
            </box>
          </geometry>
          <max_contacts>10</max_contacts>
          <surface>
            <contact>
              <ode/>
            </contact>
            <bounce/>
            <friction>
              <torsional>
                <ode/>
              </torsional>
              <ode/>
            </friction>
          </surface>
        </collision>
        <collision name='castor_collision'>
          <pose frame=''>-0.2 0 -0.12 0 -0 0</pose>
          <geometry>
            <sphere>
              <radius>0.04</radius>
            </sphere>
          </geometry>
          <surface>
            <friction>
              <ode>
                <mu>0</mu>
                <mu2>0</mu2>
                <slip1>1</slip1>
                <slip2>1</slip2>
              </ode>
              <torsional>
                <ode/>
              </torsional>
            </friction>
            <contact>
              <ode/>
            </contact>
            <bounce/>
          </surface>
          <max_contacts>10</max_contacts>
        </collision>
        <visual name='visual'>
          <pose frame=''>0 0 0.04 0 -0 0</pose>
          <geometry>
            <mesh>
              <uri>model://pioneer2dx/meshes/chassis.dae</uri>
            </mesh>
          </geometry>
        </visual>
        <visual name='castor_visual'>
          <pose frame=''>-0.2 0 -0.12 0 -0 0</pose>
          <geometry>
            <sphere>
              <radius>0.04</radius>
            </sphere>
          </geometry>
          <material>
            <script>
              <uri>file://media/materials/scripts/gazebo.material</uri>
              <name>Gazebo/FlatBlack</name>
            </script>
          </material>
        </visual>
        <self_collide>0</self_collide>
        <kinematic>0</kinematic>
      </link>
      <link name='right_wheel'>
        <pose frame=''>0.1 -0.17 0.11 -0 1.5707 1.5707</pose>
        <inertial>
          <mass>1.5</mass>
          <inertia>
            <ixx>0.0051</ixx>
            <iyy>0.0051</iyy>
            <izz>0.009</izz>
            <ixy>0</ixy>
            <ixz>0</ixz>
            <iyz>0</iyz>
          </inertia>
        </inertial>
        <collision name='collision'>
          <geometry>
            <cylinder>
              <radius>0.11</radius>
              <length>0.05</length>
            </cylinder>
          </geometry>
          <surface>
            <friction>
              <ode>
                <mu>100000</mu>
                <mu2>100000</mu2>
                <slip1>0</slip1>
                <slip2>0</slip2>
              </ode>
              <torsional>
                <ode/>
              </torsional>
            </friction>
            <contact>
              <ode/>
            </contact>
            <bounce/>
          </surface>
          <max_contacts>10</max_contacts>
        </collision>
        <visual name='visual'>
          <geometry>
            <cylinder>
              <radius>0.11</radius>
              <length>0.05</length>
            </cylinder>
          </geometry>
          <material>
            <script>
              <uri>file://media/materials/scripts/gazebo.material</uri>
              <name>Gazebo/FlatBlack</name>
            </script>
          </material>
        </visual>
        <self_collide>0</self_collide>
        <kinematic>0</kinematic>
      </link>
      <link name='left_wheel'>
        <pose frame=''>0.1 0.17 0.11 -0 1.5707 1.5707</pose>
        <inertial>
          <mass>1.5</mass>
          <inertia>
            <ixx>0.0051</ixx>
            <iyy>0.0051</iyy>
            <izz>0.009</izz>
            <ixy>0</ixy>
            <ixz>0</ixz>
            <iyz>0</iyz>
          </inertia>
        </inertial>
        <collision name='collision'>
          <geometry>
            <cylinder>
              <radius>0.11</radius>
              <length>0.05</length>
            </cylinder>
          </geometry>
          <surface>
            <friction>
              <ode>
                <mu>100000</mu>
                <mu2>100000</mu2>
                <slip1>0</slip1>
                <slip2>0</slip2>
              </ode>
              <torsional>
                <ode/>
              </torsional>
            </friction>
            <contact>
              <ode/>
            </contact>
            <bounce/>
          </surface>
          <max_contacts>10</max_contacts>
        </collision>
        <visual name='visual'>
          <geometry>
            <cylinder>
              <radius>0.11</radius>
              <length>0.05</length>
            </cylinder>
          </geometry>
          <material>
            <script>
              <uri>file://media/materials/scripts/gazebo.material</uri>
              <name>Gazebo/FlatBlack</name>
            </script>
          </material>
        </visual>
        <self_collide>0</self_collide>
        <kinematic>0</kinematic>
      </link>
      <joint name='left_wheel_hinge' type='revolute'>
        <pose frame=''>0 0 -0.03 0 -0 0</pose>
        <child>left_wheel</child>
        <parent>chassis</parent>
        <axis>
          <xyz>0 1 0</xyz>
          <use_parent_model_frame>1</use_parent_model_frame>
          <limit>
            <lower>-1e+16</lower>
            <upper>1e+16</upper>
          </limit>
          <dynamics>
            <spring_reference>0</spring_reference>
            <spring_stiffness>0</spring_stiffness>
          </dynamics>
        </axis>
      </joint>
      <joint name='right_wheel_hinge' type='revolute'>
        <pose frame=''>0 0 0.03 0 -0 0</pose>
        <child>right_wheel</child>
        <parent>chassis</parent>
        <axis>
          <xyz>0 1 0</xyz>
          <use_parent_model_frame>1</use_parent_model_frame>
          <limit>
            <lower>-1e+16</lower>
            <upper>1e+16</upper>
          </limit>
          <dynamics>
            <spring_reference>0</spring_reference>
            <spring_stiffness>0</spring_stiffness>
          </dynamics>
        </axis>
      </joint>
      <plugin name='diff_drive' filename='libDiffDrivePlugin.so'>
        <left_joint>left_wheel_hinge</left_joint>
        <right_joint>right_wheel_hinge</right_joint>
        <torque>5</torque>
      </plugin>
      <pose frame=''>-2.66075 -1.54588 0 0 -0 0</pose>
    </model>
    <model name='Construction Cone'>
      <link name='link'>
        <collision name='collision'>
          <geometry>
            <mesh>
              <scale>10 10 10</scale>
              <uri>model://construction_cone/meshes/construction_cone.dae</uri>
            </mesh>
          </geometry>
          <max_contacts>10</max_contacts>
          <surface>
            <contact>
              <ode/>
            </contact>
            <bounce/>
            <friction>
              <torsional>
                <ode/>
              </torsional>
              <ode/>
            </friction>
          </surface>
        </collision>
        <visual name='visual'>
          <geometry>
            <mesh>
              <scale>10 10 10</scale>
              <uri>model://construction_cone/meshes/construction_cone.dae</uri>
            </mesh>
          </geometry>
        </visual>
        <self_collide>0</self_collide>
        <inertial>
          <inertia>
            <ixx>1</ixx>
            <ixy>0</ixy>
            <ixz>0</ixz>
            <iyy>1</iyy>
            <iyz>0</iyz>
            <izz>1</izz>
          </inertia>
          <mass>1</mass>
        </inertial>
        <kinematic>0</kinematic>
      </link>
      <pose frame=''>-4.02775 0.424675 0 0 -0 0</pose>
    </model>
    <model name='Construction Barrel'>
      <link name='link'>
        <inertial>
          <pose frame=''>0 0 0.4 0 -0 0</pose>
          <mass>500</mass>
          <inertia>
            <ixx>51.2096</ixx>
            <iyy>51.2096</iyy>
            <izz>25</izz>
            <ixy>0</ixy>
            <ixz>0</ixz>
            <iyz>0</iyz>
          </inertia>
        </inertial>
        <collision name='collision'>
          <geometry>
            <mesh>
              <uri>model://construction_barrel/meshes/construction_barrel.dae</uri>
            </mesh>
          </geometry>
          <max_contacts>10</max_contacts>
          <surface>
            <contact>
              <ode/>
            </contact>
            <bounce/>
            <friction>
              <torsional>
                <ode/>
              </torsional>
              <ode/>
            </friction>
          </surface>
        </collision>
        <visual name='visual'>
          <geometry>
            <mesh>
              <uri>model://construction_barrel/meshes/construction_barrel.dae</uri>
            </mesh>
          </geometry>
        </visual>
        <self_collide>0</self_collide>
        <kinematic>0</kinematic>
      </link>
      <pose frame=''>-4.85142 1.96897 0 0 -0 0</pose>
    </model>
    <model name='asphalt_plane'>
      <static>1</static>
      <link name='link'>
        <collision name='collision'>
          <geometry>
            <box>
              <size>20 20 0.1</size>
            </box>
          </geometry>
          <max_contacts>10</max_contacts>
          <surface>
            <contact>
              <ode/>
            </contact>
            <bounce/>
            <friction>
              <torsional>
                <ode/>
              </torsional>
              <ode/>
            </friction>
          </surface>
        </collision>
        <visual name='visual'>
          <cast_shadows>0</cast_shadows>
          <geometry>
            <box>
              <size>20 20 0.1</size>
            </box>
          </geometry>
          <material>
            <script>
              <uri>model://asphalt_plane/materials/scripts</uri>
              <uri>model://asphalt_plane/materials/textures</uri>
              <name>vrc/asphalt</name>
            </script>
          </material>
        </visual>
        <self_collide>0</self_collide>
        <kinematic>0</kinematic>
      </link>
      <pose frame=''>2.69861 -1.43784 0 0 -0 0</pose>
    </model>
    <state world_name='default'>
      <sim_time>419 84000000</sim_time>
      <real_time>422 138445047</real_time>
      <wall_time>1567151034 540613477</wall_time>
      <iterations>419084</iterations>
      <model name='Construction Barrel'>
        <pose frame=''>-4.85795 1.98063 0.049999 3e-06 0 0.003262</pose>
        <scale>1 1 1</scale>
        <link name='link'>
          <pose frame=''>-4.85795 1.98063 0.049999 3e-06 0 0.003262</pose>
          <velocity>0 0 0 0 -0 0</velocity>
          <acceleration>2.26867 -3.66822 -0.426598 2.88888 -0.617446 0.005961</acceleration>
          <wrench>1134.34 -1834.11 -213.299 0 -0 0</wrench>
        </link>
      </model>
      <model name='Construction Cone'>
        <pose frame=''>-4.02099 0.415643 0.05 0 -0 0.012427</pose>
        <scale>1 1 1</scale>
        <link name='link'>
          <pose frame=''>-4.02099 0.415643 0.05 0 -0 0.012427</pose>
          <velocity>0 0 0 0 -0 0</velocity>
          <acceleration>0 0 -0.255897 -0.400322 0.791594 -0</acceleration>
          <wrench>0 0 -0.255897 0 -0 0</wrench>
        </link>
      </model>
      <model name='Dumpster'>
        <pose frame=''>-1.14719 0.012812 0.051377 -1e-06 -0 0.060386</pose>
        <scale>1 1 1</scale>
        <link name='link'>
          <pose frame=''>-1.14719 0.012812 0.051377 -1e-06 -0 0.060386</pose>
          <velocity>0 0 0 0 -0 0</velocity>
          <acceleration>-0.000613 0.010134 3.6988 -1.06836 -0.444477 0</acceleration>
          <wrench>-0.000613 0.010134 3.6988 0 -0 0</wrench>
        </link>
      </model>
      <model name='asphalt_plane'>
        <pose frame=''>2.69861 -1.43784 0 0 -0 0</pose>
        <scale>1 1 1</scale>
        <link name='link'>
          <pose frame=''>2.69861 -1.43784 0 0 -0 0</pose>
          <velocity>0 0 0 0 -0 0</velocity>
          <acceleration>0 0 0 0 -0 0</acceleration>
          <wrench>0 0 0 0 -0 0</wrench>
        </link>
      </model>
      <model name='cinder_block'>
        <pose frame=''>0.85761 -0.105907 0.049461 0 -0 0</pose>
        <scale>1 1 1</scale>
        <link name='link'>
          <pose frame=''>0.85761 -0.105907 0.049461 0 -0 0</pose>
          <velocity>0 0 0 0 -0 0</velocity>
          <acceleration>0 0 0 0 -0 0</acceleration>
          <wrench>0 0 0 0 -0 0</wrench>
        </link>
      </model>
      <model name='fire_hydrant'>
        <pose frame=''>-0.813705 -2.73929 0 0 -0 0</pose>
        <scale>1 1 1</scale>
        <link name='link'>
          <pose frame=''>-0.813705 -2.73929 0 0 -0 0</pose>
          <velocity>0 0 0 0 -0 0</velocity>
          <acceleration>0 0 0 0 -0 0</acceleration>
          <wrench>0 0 0 0 -0 0</wrench>
        </link>
      </model>
      <model name='ground_plane'>
        <pose frame=''>0 0 0 0 -0 0</pose>
        <scale>1 1 1</scale>
        <link name='link'>
          <pose frame=''>0 0 0 0 -0 0</pose>
          <velocity>0 0 0 0 -0 0</velocity>
          <acceleration>0 0 0 0 -0 0</acceleration>
          <wrench>0 0 0 0 -0 0</wrench>
        </link>
      </model>
      <model name='ground_plane_0'>
        <pose frame=''>0.276228 -2.32772 0 0 -0 0</pose>
        <scale>1 1 1</scale>
        <link name='link'>
          <pose frame=''>0.276228 -2.32772 0 0 -0 0</pose>
          <velocity>0 0 0 0 -0 0</velocity>
          <acceleration>0 0 0 0 -0 0</acceleration>
          <wrench>0 0 0 0 -0 0</wrench>
        </link>
      </model>
      <model name='ground_plane_1'>
        <pose frame=''>-77.2838 49.0164 0 0 -0 0</pose>
        <scale>1 1 1</scale>
        <link name='link'>
          <pose frame=''>-77.2838 49.0164 0 0 -0 0</pose>
          <velocity>0 0 0 0 -0 0</velocity>
          <acceleration>0 0 0 0 -0 0</acceleration>
          <wrench>0 0 0 0 -0 0</wrench>
        </link>
      </model>
      <model name='legged_robot'>
        <pose frame=''>-1.95407 -1.95028 -0.525 -1e-06 1e-06 -0.039216</pose>
        <scale>1 1 1</scale>
        <link name='base_left_fore'>
          <pose frame=''>-1.71758 -1.78943 0.070002 1.5707 -0.013573 -0.03921</pose>
          <velocity>0.000352 -0.000128 0.000127 -0.000232 -7.6e-05 0.000309</velocity>
          <acceleration>0.553785 -0.532978 0.821042 2.60284 -0.620116 0.664317</acceleration>
          <wrench>0.553785 -0.532978 0.821042 0 -0 0</wrench>
        </link>
        <link name='base_left_rear'>
          <pose frame=''>-2.17723 -1.77139 0.069999 1.5707 0.02476 -0.039211</pose>
          <velocity>0.000361 -0.000349 0.008109 0.000883 -0.002964 0.00029</velocity>
          <acceleration>0.576981 -1.15105 14.0596 -3.01412 1.45339 0.509843</acceleration>
          <wrench>0.576981 -1.15105 14.0596 0 -0 0</wrench>
        </link>
        <link name='base_right_fore'>
          <pose frame=''>-1.73091 -2.12916 0.070004 -1.57089 -0.475904 3.10238</pose>
          <velocity>0.000631 -0.000256 -3.3e-05 0.001286 0.002706 0.000148</velocity>
          <acceleration>0.97518 -0.767855 0.123399 -2.96212 -0.164594 0.225872</acceleration>
          <wrench>0.97518 -0.767855 0.123399 0 -0 0</wrench>
        </link>
        <link name='base_right_rear'>
          <pose frame=''>-2.19055 -2.11113 0.07 1.5707 0.019829 -0.039213</pose>
          <velocity>0.000338 -6e-05 0.007654 0.001417 -0.000336 -0.000349</velocity>
          <acceleration>0.634299 -0.756875 13.1983 -2.1673 0.203263 0.208177</acceleration>
          <wrench>0.634299 -0.756875 13.1983 0 -0 0</wrench>
        </link>
        <link name='link_left_fore_lower'>
          <pose frame=''>-1.82576 -1.57978 0.07 1.5708 0.021499 2.21501</pose>
          <velocity>-1.2e-05 -5e-06 -1.2e-05 0.000218 -0.00066 2.3e-05</velocity>
          <acceleration>-0.064424 0.034286 -0.006688 2.55606 -0.809912 2.82568</acceleration>
          <wrench>-0.128847 0.068572 -0.013377 0 -0 0</wrench>
        </link>
        <link name='link_left_fore_upper'>
          <pose frame=''>-1.71174 -1.63956 0.072501 1.55413 -0.013578 -0.039206</pose>
          <velocity>0.000148 -0.00012 0.000105 5.2e-05 -0.00028 0.000765</velocity>
          <acceleration>0.324007 -0.517852 0.61914 2.424 -1.5051 -2.11082</acceleration>
          <wrench>0.648013 -1.03571 1.23828 0 -0 0</wrench>
        </link>
        <link name='link_left_rear_lower'>
          <pose frame=''>-2.1005 -1.95 0.070004 -1.57082 -0.029846 2.51063</pose>
          <velocity>-0.000389 -0.000209 0.003746 0.025218 -0.003789 0.002882</velocity>
          <acceleration>-0.33559 -1.21065 -0.219622 0.082412 -0.698341 2.89549</acceleration>
          <wrench>-0.671179 -2.4213 -0.439245 0 -0 0</wrench>
        </link>
        <link name='link_left_rear_upper'>
          <pose frame=''>-2.18304 -1.92126 0.072499 -1.55413 0.024759 -0.039211</pose>
          <velocity>0.000164 -0.000298 0.004191 0.025975 -0.003886 -0.000685</velocity>
          <acceleration>0.23708 -1.01037 2.3777 1.74563 -0.613477 -1.61702</acceleration>
          <wrench>0.47416 -2.02074 4.7554 0 -0 0</wrench>
        </link>
        <link name='link_right_fore_lower'>
          <pose frame=''>-1.74222 -2.27889 0.070001 1.57079 0.476169 -0.003036</pose>
          <velocity>0.000123 -0.0004 -0.000305 0.019963 0.001491 0.001053</velocity>
          <acceleration>-1.15346 -1.02347 -2.32542 -1.91744 -1.01197 -2.98807</acceleration>
          <wrench>-2.30692 -2.04695 -4.65083 0 -0 0</wrench>
        </link>
        <link name='link_right_fore_upper'>
          <pose frame=''>-1.73793 -2.27898 0.067777 1.5874 -0.475904 3.10238</pose>
          <velocity>0.000174 -0.000291 -0.002138 0.016203 0.001987 -0.006255</velocity>
          <acceleration>-1.74117 -0.800109 -5.94948 -0.177156 -1.32302 0.103563</acceleration>
          <wrench>-3.48234 -1.60022 -11.899 0 -0 0</wrench>
        </link>
        <link name='link_right_rear_lower'>
          <pose frame=''>-2.10149 -2.29979 0.069996 -1.57085 -0.025929 2.4045</pose>
          <velocity>-0.000514 6.9e-05 -0.003844 0.065874 -0.004497 0.002765</velocity>
          <acceleration>-0.550283 -0.931409 -7.94804 -2.96766 0.227253 2.78175</acceleration>
          <wrench>-1.10057 -1.86282 -15.8961 0 -0 0</wrench>
        </link>
        <link name='link_right_rear_upper'>
          <pose frame=''>-2.19638 -2.261 0.072495 -1.5541 0.019828 -0.039214</pose>
          <velocity>3.8e-05 3.5e-05 -0.002157 0.065505 -0.002452 -0.001527</velocity>
          <acceleration>0.091246 -0.629998 -4.32012 0.659756 0.703716 1.49942</acceleration>
          <wrench>0.182491 -1.25999 -8.64023 0 -0 0</wrench>
        </link>
        <link name='torso'>
          <pose frame=''>-1.95407 -1.95028 0.075 -1e-06 1e-06 -0.039216</pose>
          <velocity>0.000436 -7.4e-05 0.00394 0.00273 0.01731 -8e-06</velocity>
          <acceleration>0.834121 -0.573806 6.90849 2.15488 -1.21626 -2.02586</acceleration>
          <wrench>8.34121 -5.73806 69.0849 0 -0 0</wrench>
        </link>
      </model>
      <model name='pioneer2dx'>
        <pose frame=''>-2.11653 -1.46721 0.050002 -3e-06 -9e-06 -0.153804</pose>
        <scale>1 1 1</scale>
        <link name='chassis'>
          <pose frame=''>-2.11653 -1.46721 0.210002 -3e-06 -9e-06 -0.153804</pose>
          <velocity>-0.000245 -0.001335 0.005273 0.023877 0.002584 -0.004836</velocity>
          <acceleration>-0.423934 -3.81841 10.4473 -2.52586 -1.54585 2.27176</acceleration>
          <wrench>-2.40371 -21.6504 59.2363 0 -0 0</wrench>
        </link>
        <link name='left_wheel'>
          <pose frame=''>-1.99167 -1.31453 0.160002 -1.57012 1.45903 -0.153221</pose>
          <velocity>0.000268 -0.001098 0.008647 0.010093 0.001346 -0.004874</velocity>
          <acceleration>0.771199 -3.057 17.1249 2.16529 0.28644 0.614784</acceleration>
          <wrench>1.1568 -4.58549 25.6873 0 -0 0</wrench>
        </link>
        <link name='right_wheel'>
          <pose frame=''>-2.04375 -1.65052 0.160003 -1.56979 1.4628 -0.152892</pose>
          <velocity>-0.001249 -0.000929 0.000683 0.008474 -0.012357 -0.00457</velocity>
          <acceleration>-2.57978 -2.6038 1.214 1.46288 -1.2283 1.15282</acceleration>
          <wrench>-3.86967 -3.9057 1.82099 0 -0 0</wrench>
        </link>
      </model>
      <light name='sun'>
        <pose frame=''>0 0 10 0 -0 0</pose>
      </light>
    </state>
    <gui fullscreen='0'>
      <camera name='user_camera'>
        <pose frame=''>12.6785 -9.07145 19.2266 -0 0.603643 2.71137</pose>
        <view_controller>orbit</view_controller>
        <projection_type>perspective</projection_type>
      </camera>
    </gui>
  </world>
</sdf>
